[2022-01-27 14:38:57,236] {taskinstance.py:876} INFO - Dependencies all met for <TaskInstance: cgi_40.load_data_source 2022-01-26T14:38:40.082078+00:00 [queued]>
[2022-01-27 14:38:57,247] {taskinstance.py:876} INFO - Dependencies all met for <TaskInstance: cgi_40.load_data_source 2022-01-26T14:38:40.082078+00:00 [queued]>
[2022-01-27 14:38:57,247] {taskinstance.py:1067} INFO - 
--------------------------------------------------------------------------------
[2022-01-27 14:38:57,247] {taskinstance.py:1068} INFO - Starting attempt 1 of 1
[2022-01-27 14:38:57,247] {taskinstance.py:1069} INFO - 
--------------------------------------------------------------------------------
[2022-01-27 14:38:57,252] {taskinstance.py:1087} INFO - Executing <Task(BashOperator): load_data_source> on 2022-01-26T14:38:40.082078+00:00
[2022-01-27 14:38:57,259] {standard_task_runner.py:52} INFO - Started process 56 to run task
[2022-01-27 14:38:57,262] {standard_task_runner.py:76} INFO - Running: ['***', 'tasks', 'run', 'cgi_40', 'load_data_source', '2022-01-26T14:38:40.082078+00:00', '--job-id', '3', '--pool', 'default_pool', '--raw', '--subdir', 'DAGS_FOLDER/cgi40_dag.py', '--cfg-path', '/tmp/tmpc751wb1x', '--error-file', '/tmp/tmpn5_hugds']
[2022-01-27 14:38:57,262] {standard_task_runner.py:77} INFO - Job 3: Subtask load_data_source
[2022-01-27 14:38:57,290] {logging_mixin.py:104} INFO - Running <TaskInstance: cgi_40.load_data_source 2022-01-26T14:38:40.082078+00:00 [running]> on host bb053c5f0074
[2022-01-27 14:38:57,321] {taskinstance.py:1282} INFO - Exporting the following env vars:
AIRFLOW_CTX_DAG_EMAIL=oulespaul@gmail.com
AIRFLOW_CTX_DAG_OWNER=ETDA
AIRFLOW_CTX_DAG_ID=cgi_40
AIRFLOW_CTX_TASK_ID=load_data_source
AIRFLOW_CTX_EXECUTION_DATE=2022-01-26T14:38:40.082078+00:00
AIRFLOW_CTX_DAG_RUN_ID=scheduled__2022-01-26T14:38:40.082078+00:00
[2022-01-27 14:38:57,321] {subprocess.py:52} INFO - Tmp dir root location: 
 /tmp
[2022-01-27 14:38:57,322] {subprocess.py:63} INFO - Running command: ['bash', '-c', 'cd /opt/***/dags/data_source && curl -LfO "https://www.teknologisk.dk/_/media/76459_GCR%2017-19%20Dataset.xlsx"']
[2022-01-27 14:38:57,329] {subprocess.py:75} INFO - Output:
[2022-01-27 14:38:57,331] {subprocess.py:79} INFO - bash: line 0: cd: /opt/***/dags/data_source: No such file or directory
[2022-01-27 14:38:57,331] {subprocess.py:83} INFO - Command exited with return code 1
[2022-01-27 14:38:57,337] {taskinstance.py:1481} ERROR - Task failed with exception
Traceback (most recent call last):
  File "/home/airflow/.local/lib/python3.6/site-packages/airflow/models/taskinstance.py", line 1137, in _run_raw_task
    self._prepare_and_execute_task_with_callbacks(context, task)
  File "/home/airflow/.local/lib/python3.6/site-packages/airflow/models/taskinstance.py", line 1311, in _prepare_and_execute_task_with_callbacks
    result = self._execute_task(context, task_copy)
  File "/home/airflow/.local/lib/python3.6/site-packages/airflow/models/taskinstance.py", line 1341, in _execute_task
    result = task_copy.execute(context=context)
  File "/home/airflow/.local/lib/python3.6/site-packages/airflow/operators/bash.py", line 180, in execute
    raise AirflowException('Bash command failed. The command returned a non-zero exit code.')
airflow.exceptions.AirflowException: Bash command failed. The command returned a non-zero exit code.
[2022-01-27 14:38:57,339] {taskinstance.py:1531} INFO - Marking task as FAILED. dag_id=cgi_40, task_id=load_data_source, execution_date=20220126T143840, start_date=20220127T143857, end_date=20220127T143857
[2022-01-27 14:38:57,353] {local_task_job.py:151} INFO - Task exited with return code 1
