[2022-01-27 14:47:31,446] {taskinstance.py:876} INFO - Dependencies all met for <TaskInstance: cgi_40.etl 2022-01-27T14:47:30.349603+00:00 [queued]>
[2022-01-27 14:47:31,455] {taskinstance.py:876} INFO - Dependencies all met for <TaskInstance: cgi_40.etl 2022-01-27T14:47:30.349603+00:00 [queued]>
[2022-01-27 14:47:31,455] {taskinstance.py:1067} INFO - 
--------------------------------------------------------------------------------
[2022-01-27 14:47:31,456] {taskinstance.py:1068} INFO - Starting attempt 1 of 1
[2022-01-27 14:47:31,456] {taskinstance.py:1069} INFO - 
--------------------------------------------------------------------------------
[2022-01-27 14:47:31,465] {taskinstance.py:1087} INFO - Executing <Task(PythonOperator): etl> on 2022-01-27T14:47:30.349603+00:00
[2022-01-27 14:47:31,475] {standard_task_runner.py:52} INFO - Started process 77 to run task
[2022-01-27 14:47:31,479] {standard_task_runner.py:76} INFO - Running: ['***', 'tasks', 'run', 'cgi_40', 'etl', '2022-01-27T14:47:30.349603+00:00', '--job-id', '11', '--pool', 'default_pool', '--raw', '--subdir', 'DAGS_FOLDER/cgi40_dag.py', '--cfg-path', '/tmp/tmp4ihxexqr', '--error-file', '/tmp/tmp60p5o612']
[2022-01-27 14:47:31,479] {standard_task_runner.py:77} INFO - Job 11: Subtask etl
[2022-01-27 14:47:31,512] {logging_mixin.py:104} INFO - Running <TaskInstance: cgi_40.etl 2022-01-27T14:47:30.349603+00:00 [running]> on host bb053c5f0074
[2022-01-27 14:47:31,545] {taskinstance.py:1282} INFO - Exporting the following env vars:
AIRFLOW_CTX_DAG_EMAIL=oulespaul@gmail.com
AIRFLOW_CTX_DAG_OWNER=ETDA
AIRFLOW_CTX_DAG_ID=cgi_40
AIRFLOW_CTX_TASK_ID=etl
AIRFLOW_CTX_EXECUTION_DATE=2022-01-27T14:47:30.349603+00:00
AIRFLOW_CTX_DAG_RUN_ID=manual__2022-01-27T14:47:30.349603+00:00
[2022-01-27 14:47:31,545] {logging_mixin.py:104} INFO - etl on progress...
[2022-01-27 14:47:31,678] {taskinstance.py:1481} ERROR - Task failed with exception
Traceback (most recent call last):
  File "/home/airflow/.local/lib/python3.6/site-packages/airflow/models/taskinstance.py", line 1137, in _run_raw_task
    self._prepare_and_execute_task_with_callbacks(context, task)
  File "/home/airflow/.local/lib/python3.6/site-packages/airflow/models/taskinstance.py", line 1311, in _prepare_and_execute_task_with_callbacks
    result = self._execute_task(context, task_copy)
  File "/home/airflow/.local/lib/python3.6/site-packages/airflow/models/taskinstance.py", line 1341, in _execute_task
    result = task_copy.execute(context=context)
  File "/home/airflow/.local/lib/python3.6/site-packages/airflow/operators/python.py", line 150, in execute
    return_value = self.execute_callable()
  File "/home/airflow/.local/lib/python3.6/site-packages/airflow/operators/python.py", line 161, in execute_callable
    return self.python_callable(*self.op_args, **self.op_kwargs)
  File "/opt/airflow/dags/cgi40_dag.py", line 13, in etl
    sheet_name='Data', skiprows=2, engine="openpyxl").drop(0)
  File "/home/airflow/.local/lib/python3.6/site-packages/pandas/util/_decorators.py", line 296, in wrapper
    return func(*args, **kwargs)
  File "/home/airflow/.local/lib/python3.6/site-packages/pandas/io/excel/_base.py", line 304, in read_excel
    io = ExcelFile(io, engine=engine)
  File "/home/airflow/.local/lib/python3.6/site-packages/pandas/io/excel/_base.py", line 867, in __init__
    self._reader = self._engines[engine](self._io)
  File "/home/airflow/.local/lib/python3.6/site-packages/pandas/io/excel/_openpyxl.py", line 480, in __init__
    super().__init__(filepath_or_buffer)
  File "/home/airflow/.local/lib/python3.6/site-packages/pandas/io/excel/_base.py", line 353, in __init__
    self.book = self.load_workbook(filepath_or_buffer)
  File "/home/airflow/.local/lib/python3.6/site-packages/pandas/io/excel/_openpyxl.py", line 492, in load_workbook
    filepath_or_buffer, read_only=True, data_only=True, keep_links=False
  File "/home/airflow/.local/lib/python3.6/site-packages/openpyxl/reader/excel.py", line 316, in load_workbook
    data_only, keep_links)
  File "/home/airflow/.local/lib/python3.6/site-packages/openpyxl/reader/excel.py", line 124, in __init__
    self.archive = _validate_archive(fn)
  File "/home/airflow/.local/lib/python3.6/site-packages/openpyxl/reader/excel.py", line 96, in _validate_archive
    archive = ZipFile(filename, 'r')
  File "/usr/local/lib/python3.6/zipfile.py", line 1113, in __init__
    self.fp = io.open(file, filemode)
FileNotFoundError: [Errno 2] No such file or directory: '/opt/airflow/dags/data_source/76459_GCR%2017-19%20Dataset.xlsx'
[2022-01-27 14:47:31,680] {taskinstance.py:1531} INFO - Marking task as FAILED. dag_id=cgi_40, task_id=etl, execution_date=20220127T144730, start_date=20220127T144731, end_date=20220127T144731
[2022-01-27 14:47:31,732] {local_task_job.py:151} INFO - Task exited with return code 1
