[2022-01-27 16:17:45,996] {taskinstance.py:876} INFO - Dependencies all met for <TaskInstance: cgi_40.load_to_hdfs 2022-01-27T16:17:35.471531+00:00 [queued]>
[2022-01-27 16:17:46,007] {taskinstance.py:876} INFO - Dependencies all met for <TaskInstance: cgi_40.load_to_hdfs 2022-01-27T16:17:35.471531+00:00 [queued]>
[2022-01-27 16:17:46,007] {taskinstance.py:1067} INFO - 
--------------------------------------------------------------------------------
[2022-01-27 16:17:46,007] {taskinstance.py:1068} INFO - Starting attempt 1 of 1
[2022-01-27 16:17:46,007] {taskinstance.py:1069} INFO - 
--------------------------------------------------------------------------------
[2022-01-27 16:17:46,015] {taskinstance.py:1087} INFO - Executing <Task(PythonOperator): load_to_hdfs> on 2022-01-27T16:17:35.471531+00:00
[2022-01-27 16:17:46,022] {standard_task_runner.py:52} INFO - Started process 92 to run task
[2022-01-27 16:17:46,025] {standard_task_runner.py:76} INFO - Running: ['***', 'tasks', 'run', 'cgi_40', 'load_to_hdfs', '2022-01-27T16:17:35.471531+00:00', '--job-id', '11', '--pool', 'default_pool', '--raw', '--subdir', 'DAGS_FOLDER/cgi40_dag.py', '--cfg-path', '/tmp/tmp4srjv0pf', '--error-file', '/tmp/tmp83y43434']
[2022-01-27 16:17:46,025] {standard_task_runner.py:77} INFO - Job 11: Subtask load_to_hdfs
[2022-01-27 16:17:46,054] {logging_mixin.py:104} INFO - Running <TaskInstance: cgi_40.load_to_hdfs 2022-01-27T16:17:35.471531+00:00 [running]> on host ca77e06d0f72
[2022-01-27 16:17:46,090] {taskinstance.py:1282} INFO - Exporting the following env vars:
AIRFLOW_CTX_DAG_EMAIL=oulespaul@gmail.com
AIRFLOW_CTX_DAG_OWNER=ETDA
AIRFLOW_CTX_DAG_ID=cgi_40
AIRFLOW_CTX_TASK_ID=load_to_hdfs
AIRFLOW_CTX_EXECUTION_DATE=2022-01-27T16:17:35.471531+00:00
AIRFLOW_CTX_DAG_RUN_ID=manual__2022-01-27T16:17:35.471531+00:00
[2022-01-27 16:17:46,104] {taskinstance.py:1481} ERROR - Task failed with exception
Traceback (most recent call last):
  File "/home/airflow/.local/lib/python3.6/site-packages/airflow/models/taskinstance.py", line 1137, in _run_raw_task
    self._prepare_and_execute_task_with_callbacks(context, task)
  File "/home/airflow/.local/lib/python3.6/site-packages/airflow/models/taskinstance.py", line 1311, in _prepare_and_execute_task_with_callbacks
    result = self._execute_task(context, task_copy)
  File "/home/airflow/.local/lib/python3.6/site-packages/airflow/models/taskinstance.py", line 1341, in _execute_task
    result = task_copy.execute(context=context)
  File "/home/airflow/.local/lib/python3.6/site-packages/airflow/operators/python.py", line 150, in execute
    return_value = self.execute_callable()
  File "/home/airflow/.local/lib/python3.6/site-packages/airflow/operators/python.py", line 161, in execute_callable
    return self.python_callable(*self.op_args, **self.op_kwargs)
  File "/opt/airflow/dags/cgi40_dag.py", line 929, in store_to_hdfs
    my_data = csv.read(file_data, delimiter=',')
AttributeError: module 'csv' has no attribute 'read'
[2022-01-27 16:17:46,106] {taskinstance.py:1531} INFO - Marking task as FAILED. dag_id=cgi_40, task_id=load_to_hdfs, execution_date=20220127T161735, start_date=20220127T161745, end_date=20220127T161746
[2022-01-27 16:17:46,157] {local_task_job.py:151} INFO - Task exited with return code 1
