[2022-01-27 16:18:33,407] {taskinstance.py:876} INFO - Dependencies all met for <TaskInstance: cgi_40.load_to_hdfs 2022-01-27T16:18:21.052373+00:00 [queued]>
[2022-01-27 16:18:33,415] {taskinstance.py:876} INFO - Dependencies all met for <TaskInstance: cgi_40.load_to_hdfs 2022-01-27T16:18:21.052373+00:00 [queued]>
[2022-01-27 16:18:33,415] {taskinstance.py:1067} INFO - 
--------------------------------------------------------------------------------
[2022-01-27 16:18:33,415] {taskinstance.py:1068} INFO - Starting attempt 1 of 1
[2022-01-27 16:18:33,415] {taskinstance.py:1069} INFO - 
--------------------------------------------------------------------------------
[2022-01-27 16:18:33,423] {taskinstance.py:1087} INFO - Executing <Task(PythonOperator): load_to_hdfs> on 2022-01-27T16:18:21.052373+00:00
[2022-01-27 16:18:33,430] {standard_task_runner.py:52} INFO - Started process 100 to run task
[2022-01-27 16:18:33,433] {standard_task_runner.py:76} INFO - Running: ['***', 'tasks', 'run', 'cgi_40', 'load_to_hdfs', '2022-01-27T16:18:21.052373+00:00', '--job-id', '14', '--pool', 'default_pool', '--raw', '--subdir', 'DAGS_FOLDER/cgi40_dag.py', '--cfg-path', '/tmp/tmpr3mf6mvf', '--error-file', '/tmp/tmpml09od4q']
[2022-01-27 16:18:33,433] {standard_task_runner.py:77} INFO - Job 14: Subtask load_to_hdfs
[2022-01-27 16:18:33,459] {logging_mixin.py:104} INFO - Running <TaskInstance: cgi_40.load_to_hdfs 2022-01-27T16:18:21.052373+00:00 [running]> on host ca77e06d0f72
[2022-01-27 16:18:33,487] {taskinstance.py:1282} INFO - Exporting the following env vars:
AIRFLOW_CTX_DAG_EMAIL=oulespaul@gmail.com
AIRFLOW_CTX_DAG_OWNER=ETDA
AIRFLOW_CTX_DAG_ID=cgi_40
AIRFLOW_CTX_TASK_ID=load_to_hdfs
AIRFLOW_CTX_EXECUTION_DATE=2022-01-27T16:18:21.052373+00:00
AIRFLOW_CTX_DAG_RUN_ID=manual__2022-01-27T16:18:21.052373+00:00
[2022-01-27 16:18:33,508] {taskinstance.py:1481} ERROR - Task failed with exception
Traceback (most recent call last):
  File "/usr/local/lib/python3.6/http/client.py", line 1006, in send
    self.sock.sendall(data)
TypeError: a bytes-like object is required, not 'list'

During handling of the above exception, another exception occurred:

Traceback (most recent call last):
  File "/home/airflow/.local/lib/python3.6/site-packages/airflow/models/taskinstance.py", line 1137, in _run_raw_task
    self._prepare_and_execute_task_with_callbacks(context, task)
  File "/home/airflow/.local/lib/python3.6/site-packages/airflow/models/taskinstance.py", line 1311, in _prepare_and_execute_task_with_callbacks
    result = self._execute_task(context, task_copy)
  File "/home/airflow/.local/lib/python3.6/site-packages/airflow/models/taskinstance.py", line 1341, in _execute_task
    result = task_copy.execute(context=context)
  File "/home/airflow/.local/lib/python3.6/site-packages/airflow/operators/python.py", line 150, in execute
    return_value = self.execute_callable()
  File "/home/airflow/.local/lib/python3.6/site-packages/airflow/operators/python.py", line 161, in execute_callable
    return self.python_callable(*self.op_args, **self.op_kwargs)
  File "/opt/airflow/dags/cgi40_dag.py", line 931, in store_to_hdfs
    my_dir+'/CGI_4.0_2017_2019_{}.csv'.format(ingest_date), my_data, overwrite=True)
  File "/home/airflow/.local/lib/python3.6/site-packages/pywebhdfs/webhdfs.py", line 115, in create_file
    **self.request_extra_opts)
  File "/home/airflow/.local/lib/python3.6/site-packages/requests/api.py", line 134, in put
    return request('put', url, data=data, **kwargs)
  File "/home/airflow/.local/lib/python3.6/site-packages/requests/api.py", line 61, in request
    return session.request(method=method, url=url, **kwargs)
  File "/home/airflow/.local/lib/python3.6/site-packages/requests/sessions.py", line 542, in request
    resp = self.send(prep, **send_kwargs)
  File "/home/airflow/.local/lib/python3.6/site-packages/requests/sessions.py", line 655, in send
    r = adapter.send(request, **kwargs)
  File "/home/airflow/.local/lib/python3.6/site-packages/requests/adapters.py", line 472, in send
    low_conn.send(i)
  File "/usr/local/lib/python3.6/http/client.py", line 1010, in send
    self.sock.sendall(d)
TypeError: a bytes-like object is required, not 'str'
[2022-01-27 16:18:33,510] {taskinstance.py:1531} INFO - Marking task as FAILED. dag_id=cgi_40, task_id=load_to_hdfs, execution_date=20220127T161821, start_date=20220127T161833, end_date=20220127T161833
[2022-01-27 16:18:33,524] {local_task_job.py:151} INFO - Task exited with return code 1
